Workbook

Sheet Koordinaten
P1: 1441
C3: Koordinaten
D4: Standort | E4: Ziel
C5: Ostwert | D5: 481 | E5: 707 | F5: =IF(D5-E5=0,D5+0.0001,D5) -> 481 | R5: 225
C6: Nordwert | D6: 473 | E6: 428 | F6: =IF(D6-E6=0,D6+0.0001,D6) -> 473 | R6: =D6*3.5 -> 1655.5
C7: Höhe | D7: 95 | E7: 145
C10: Einstellungen
D12: Anzahl der Ringe: | E12: 4 | F12: Stk.
D14: Entfernung zum Ziel: | E14: =((D5-E5)^2+(D6-E6)^2)^(1/2)*10 -> 2304.3654 | F14: Meter
D15: ELEV: | E15: =VLOOKUP($E$12,Tabelle1!$G$4:$AB$8,12,FALSE) -> 1134.6016 | F15: MIL
D16: ∆ ELEV Höhe | E16: =VLOOKUP(E12,Tabelle1!$G$11:$R$15,3,FALSE) -> 9.1136667 | F16: MIL
D17: ELEV Gesamt | E17: =IF((D7-E7)>0,E15+E16,E15-E16) -> 1125.488 | F17: MIL
D18: Flugzeit | E18: {=INDEX('Flg Zeiten'!E3:I35,VLOOKUP(ROUND(E14/1000,1)*1000,'Flg Zeiten'!C3:D35,2,FALSE),1+E12)} -> 32.7 | F18: Sek
D20: Azimut
D21: Winkel | E21: =IF((F6-E6)<0,IF((F5-E5)>0,360+(ATAN((F5-E5)/(F6-E6))*180/PI()),IF((F5-E5)<0,0+(ATAN((F5-E5)/(F6-E6))*180/PI()))),IF((F5-E5)<0,180+(ATAN((F5-E5)/(F6-E6))*180/PI()),180+(ATAN((F5-E5)/(F6-E6))*180/PI()))) -> 101.26117 | F21: Grad
D22: Winkel | E22: =E21/360*6400 -> 1800.1986 | F22: MIL
C25: Folge
D26: Aktivieren | E26: NEIN
D27: in Richtung | E27: N | F27: =IF(ISERROR(VLOOKUP(E27,Tabelle1!$AT$25:$AV$32,3,FALSE)),"",VLOOKUP(E27,Tabelle1!$AT$25:$AV$32,3,FALSE)) -> ↑
E29: 1. | F29: 2. | G29: 3. | H29: 4. | I29: 5. | J29: 6. | K29: 7. | L29: 8. | M29: 9. | N29: 10.
C30: Entfernung | D30: ELEV | E30: =VLOOKUP($E$27,Tabelle1!$AO$3:$DG$19,6,FALSE) -> 1125.488 | F30: =VLOOKUP($E$27,Tabelle1!$AO$3:$DG$19,13,FALSE) -> 1126.5822 | G30: =VLOOKUP($E$27,Tabelle1!$AO$3:$DG$19,20,FALSE) -> 1127.6249 | H30: =VLOOKUP($E$27,Tabelle1!$AO$3:$DG$19,27,FALSE) -> 1128.6163 | I30: =VLOOKUP($E$27,Tabelle1!$AO$3:$DG$19,34,FALSE) -> 1129.5567 | J30: =VLOOKUP($E$27,Tabelle1!$AO$3:$DG$19,41,FALSE) -> 1130.4463 | K30: =VLOOKUP($E$27,Tabelle1!$AO$3:$DG$19,48,FALSE) -> 1131.2854 | L30: =VLOOKUP($E$27,Tabelle1!$AO$3:$DG$19,55,FALSE) -> 1132.0742 | M30: =VLOOKUP($E$27,Tabelle1!$AO$3:$DG$19,62,FALSE) -> 1132.8128 | N30: =VLOOKUP($E$27,Tabelle1!$AO$3:$DG$19,69,FALSE) -> 1133.5014
C31: Azimut | D31: Winkel | E31: =VLOOKUP($E$27,Tabelle1!$AO$3:$DG$19,8,FALSE) -> 1800.1986 | F31: =VLOOKUP($E$27,Tabelle1!$AO$3:$DG$19,15,FALSE) -> 1791.5137 | G31: =VLOOKUP($E$27,Tabelle1!$AO$3:$DG$19,22,FALSE) -> 1782.8006 | H31: =VLOOKUP($E$27,Tabelle1!$AO$3:$DG$19,29,FALSE) -> 1774.0604 | I31: =VLOOKUP($E$27,Tabelle1!$AO$3:$DG$19,36,FALSE) -> 1765.2942 | J31: =VLOOKUP($E$27,Tabelle1!$AO$3:$DG$19,43,FALSE) -> 1756.5032 | K31: =VLOOKUP($E$27,Tabelle1!$AO$3:$DG$19,50,FALSE) -> 1747.6887 | L31: =VLOOKUP($E$27,Tabelle1!$AO$3:$DG$19,57,FALSE) -> 1738.8518 | M31: =VLOOKUP($E$27,Tabelle1!$AO$3:$DG$19,64,FALSE) -> 1729.9939 | N31: =VLOOKUP($E$27,Tabelle1!$AO$3:$DG$19,71,FALSE) -> 1721.1161

Sheet Erklärungen

Sheet Flg Zeiten
E1: Ringe
C2: Entfernung | D2: Hilfswert | E2: 0 | F2: 1 | G2: 2 | H2: 3 | I2: 4
C3: 50 | D3: 1 | E3: 13.2 | J3: Zeit in Sekunden
C4: =C3+50 -> 100 | D4: =D3+1 -> 2 | E4: 13.2 | F4: 20
C5: =C4+50 -> 150 | D5: =D4+1 -> 3 | E5: 13
C6: =C5+50 -> 200 | D6: =D5+1 -> 4 | E6: 12.8 | F6: 19.9 | G6: 26.6
C7: =C6+50 -> 250 | D7: =D6+1 -> 5 | E7: 12.6
C8: =C7+50 -> 300 | D8: =D7+1 -> 6 | E8: 12.3 | F8: 19.7 | G8: 26.5 | H8: 31.7
C9: =C8+50 -> 350 | D9: =D8+1 -> 7 | E9: 11.7
C10: =C9+50 -> 400 | D10: =D9+1 -> 8 | E10: 10.7 | F10: 19.5 | G10: 26.4 | H10: 31.6 | I10: 36.3
C11: =C10+100 -> 500 | D11: =D10+1 -> 9 | F11: 19.2 | G11: 26.3 | H11: 31.6 | I11: 36.2
C12: =C11+100 -> 600 | D12: =D11+1 -> 10 | F12: 18.8 | G12: 26.2 | H12: 31.5 | I12: 36.2
C13: =C12+100 -> 700 | D13: =D12+1 -> 11 | F13: 18.3 | G13: 26 | H13: 31.4 | I13: 36.1
C14: =C13+100 -> 800 | D14: =D13+1 -> 12 | F14: 17.5 | G14: 25.8 | H14: 31.3 | I14: 36
C15: =C14+100 -> 900 | D15: =D14+1 -> 13 | F15: 16.1 | G15: 25.5 | H15: 31.1 | I15: 35.9
C16: =C15+100 -> 1000 | D16: =D15+1 -> 14 | G16: 25.2 | H16: 31 | I16: 35.8
C17: =C16+100 -> 1100 | D17: =D16+1 -> 15 | G17: 24.9 | H17: 30.8 | I17: 35.7
C18: =C17+100 -> 1200 | D18: =D17+1 -> 16 | G18: 24.4 | H18: 30.6 | I18: 35.6
C19: =C18+100 -> 1300 | D19: =D18+1 -> 17 | G19: 23.9 | H19: 30.3 | I19: 35.4
C20: =C19+100 -> 1400 | D20: =D19+1 -> 18 | G20: 23.2 | H20: 30.1 | I20: 35.3
C21: =C20+100 -> 1500 | D21: =D20+1 -> 19 | G21: 22.3 | H21: 29.7 | I21: 35.1
C22: =C21+100 -> 1600 | D22: =D21+1 -> 20 | G22: 20.9 | H22: 29.4 | I22: 34.9
C23: =C22+100 -> 1700 | D23: =D22+1 -> 21 | H23: 29 | I23: 34.6
C24: =C23+100 -> 1800 | D24: =D23+1 -> 22 | H24: 28.5 | I24: 34.4
C25: =C24+100 -> 1900 | D25: =D24+1 -> 23 | H25: 28 | I25: 34.1
C26: =C25+100 -> 2000 | D26: =D25+1 -> 24 | H26: 27.3 | I26: 33.8
C27: =C26+100 -> 2100 | D27: =D26+1 -> 25 | H27: 26.5 | I27: 33.5
C28: =C27+100 -> 2200 | D28: =D27+1 -> 26 | H28: 25.3 | I28: 33.1
C29: =C28+100 -> 2300 | D29: =D28+1 -> 27 | H29: 22.7 | I29: 32.7
C30: =C29+100 -> 2400 | D30: =D29+1 -> 28 | I30: 32.2
C31: =C30+100 -> 2500 | D31: =D30+1 -> 29 | I31: 31.7
C32: =C31+100 -> 2600 | D32: =D31+1 -> 30 | I32: 31
C33: =C32+100 -> 2700 | D33: =D32+1 -> 31 | I33: 30.3
C34: =C33+100 -> 2800 | D34: =D33+1 -> 32 | I34: 29.2
C35: =C34+100 -> 2900 | D35: =D34+1 -> 33 | I35: 27.7

Sheet Tabelle1
S1: Polynome Flugbahn
H2: Entfernung Ziel | AP2: 1. | AW2: 2. | BD2: 3. | BK2: 4. | BR2: 5. | BY2: 6. | CF2: 7. | CM2: 8. | CT2: 9. | DA2: 10.
H3: 1. | I3: 2. | J3: 3. | K3: 4. | L3: 5. | M3: 6. | N3: 7. | O3: 8. | P3: 9. | Q3: 10. | S3: 1. | T3: 2. | U3: 3. | V3: 4. | W3: 5. | X3: 6. | Y3: 7. | Z3: 8. | AA3: 9. | AB3: 10. | AD3: x1 | AE3: x2 | AF3: x3 | AG3: x4 | AH3: x5 | AI3: x6 | AP3: OW | AQ3: NW | AR3: Entf m | AS3: ELEV MIL | AT3: ELEV ges | AU3: Wi ° | AV3: WI MIL | AW3: OW | AX3: NW | AY3: Entf m | AZ3: ELEV MIL | BA3: ELEV ges | BB3: Wi ° | BC3: WI MIL | BD3: OW | BE3: NW | BF3: Entf m | BG3: ELEV MIL | BH3: ELEV ges | BI3: Wi ° | BJ3: WI MIL | BK3: OW | BL3: NW | BM3: Entf m | BN3: ELEV MIL | BO3: ELEV ges | BP3: Wi ° | BQ3: WI MIL | BR3: OW | BS3: NW | BT3: Entf m | BU3: ELEV MIL | BV3: ELEV ges | BW3: Wi ° | BX3: WI MIL | BY3: OW | BZ3: NW | CA3: Entf m | CB3: ELEV MIL | CC3: ELEV ges | CD3: Wi ° | CE3: WI MIL | CF3: OW | CG3: NW | CH3: Entf m | CI3: ELEV MIL | CJ3: ELEV ges | CK3: Wi ° | CL3: WI MIL | CM3: OW | CN3: NW | CO3: Entf m | CP3: ELEV MIL | CQ3: ELEV ges | CR3: Wi ° | CS3: WI MIL | CT3: OW | CU3: NW | CV3: Entf m | CW3: ELEV MIL | CX3: ELEV ges | CY3: Wi ° | CZ3: WI MIL | DA3: OW | DB3: NW | DC3: Entf m | DD3: ELEV MIL | DE3: ELEV ges | DF3: Wi ° | DG3: WI MIL
F4: mil - 0 Ringe | G4: 0 | H4: =Koordinaten!$E$14 -> 2304.3654 | I4: =Tabelle1!$AY$4 -> 2300.5434 | J4: =Tabelle1!$BF$4 -> 2296.8892 | K4: =Tabelle1!$BM$4 -> 2293.4036 | L4: =Tabelle1!$BT$4 -> 2290.0873 | M4: =Tabelle1!$CA$4 -> 2286.9412 | N4: =Tabelle1!$CH$4 -> 2283.9658 | O4: =Tabelle1!$CO$4 -> 2281.162 | P4: =Tabelle1!$CV$4 -> 2278.5302 | Q4: =Tabelle1!$DC$4 -> 2276.0712 | R4: =IF(H4>400, "n.M.",S4) -> n.M. | S4: =$AG$4*H4^4+$AF$4*H4^3+$AE$4*H4^2+$AD$4*H4+$AC$4 -> -1032061.1 | T4: =$AG$4*I4^4+$AF$4*I4^3+$AE$4*I4^2+$AD$4*I4+$AC$4 -> -1024680.2 | U4: =$AG$4*J4^4+$AF$4*J4^3+$AE$4*J4^2+$AD$4*J4+$AC$4 -> -1017660.3 | V4: =$AG$4*K4^4+$AF$4*K4^3+$AE$4*K4^2+$AD$4*K4+$AC$4 -> -1010998.1 | W4: =$AG$4*L4^4+$AF$4*L4^3+$AE$4*L4^2+$AD$4*L4+$AC$4 -> -1004689.9 | X4: =$AG$4*M4^4+$AF$4*M4^3+$AE$4*M4^2+$AD$4*M4+$AC$4 -> -998732.66 | Y4: =$AG$4*N4^4+$AF$4*N4^3+$AE$4*N4^2+$AD$4*N4+$AC$4 -> -993123.24 | Z4: =$AG$4*O4^4+$AF$4*O4^3+$AE$4*O4^2+$AD$4*O4+$AC$4 -> -987858.76 | ... AB4: =$AG$4*Q4^4+$AF$4*Q4^3+$AE$4*Q4^2+$AD$4*Q4+$AC$4 -> -978353.89 | AC4: 1574.89 | AD4: =-0.348741 -> -0.348741 | AE4: =-0.00885985 -> -0.00885985 | AF4: 3.46566e-05 | AG4: =-0.00000005 -> -5e-08 | AN4: 1 | AO4: N | AP4: =Koordinaten!$E$5 -> 707 | AQ4: =Koordinaten!$E$6 -> 428 | AR4: =((Koordinaten!$D$5-AP4)^2+(Koordinaten!$D$6-AQ4)^2)^(1/2)*10 -> 2304.3654 | AS4: =VLOOKUP(Koordinaten!$E$12,Tabelle1!$G$4:$AB$8,13,FALSE) -> 1134.6016 | AT4: =IF((Koordinaten!$D$7-Koordinaten!$E$7)>0,AS4+Koordinaten!$E$16,AS4-Koordinaten!$E$16) -> 1125.488 | AU4: =IF((Koordinaten!$F$6-AQ4)<0,IF((Koordinaten!$F$5-AP4)>0,360+(ATAN((Koordinaten!$F$5-AP4)/(Koordinaten!$F$6-AQ4))*180/PI()),IF((Koordinaten!$F$5-AP4)<0,0+(ATAN((Koordinaten!$F$5-AP4)/(Koordinaten!$F$6-AQ4))*180/PI()))),IF((Koordinaten!$F$5-AP4)<0,180+(ATAN((Koordinaten!$F$5-AP4)/(Koordinaten!$F$6-AQ4))*180/PI()),180+(ATAN((Koordinaten!$F$5-AP4)/(Koordinaten!$F$6-AQ4))*180/PI()))) -> 101.26117 | AV4: =AU4/360*6400 -> 1800.1986 | AW4: =AP4 -> 707 | AX4: =AQ4+2 -> 430 | AY4: =((Koordinaten!$D$5-AW4)^2+(Koordinaten!$D$6-AX4)^2)^(1/2)*10 -> 2300.5434 | AZ4: =VLOOKUP(Koordinaten!$E$12,Tabelle1!$G$4:$AB$8,14,FALSE) -> 1135.6959 | BA4: =IF((Koordinaten!$D$7-Koordinaten!$E$7)>0,AZ4+Koordinaten!$E$16,AZ4-Koordinaten!$E$16) -> 1126.5822 | BB4: =IF((Koordinaten!$F$6-AX4)<0,IF((Koordinaten!$F$5-AW4)>0,360+(ATAN((Koordinaten!$F$5-AW4)/(Koordinaten!$F$6-AX4))*180/PI()),IF((Koordinaten!$F$5-AW4)<0,0+(ATAN((Koordinaten!$F$5-AW4)/(Koordinaten!$F$6-AX4))*180/PI()))),IF((Koordinaten!$F$5-AW4)<0,180+(ATAN((Koordinaten!$F$5-AW4)/(Koordinaten!$F$6-AX4))*180/PI()),180+(ATAN((Koordinaten!$F$5-AW4)/(Koordinaten!$F$6-AX4))*180/PI()))) -> 100.77265 | BC4: =BB4/360*6400 -> 1791.5137 | BD4: =AW4 -> 707 | BE4: =AX4+2 -> 432 | BF4: =((Koordinaten!$D$5-BD4)^2+(Koordinaten!$D$6-BE4)^2)^(1/2)*10 -> 2296.8892 | BG4: =VLOOKUP(Koordinaten!$E$12,Tabelle1!$G$4:$AB$8,15,FALSE) -> 1136.7386 | BH4: =IF((Koordinaten!$D$7-Koordinaten!$E$7)>0,BG4+Koordinaten!$E$16,BG4-Koordinaten!$E$16) -> 1127.6249 | BI4: =IF((Koordinaten!$F$6-BE4)<0,IF((Koordinaten!$F$5-BD4)>0,360+(ATAN((Koordinaten!$F$5-BD4)/(Koordinaten!$F$6-BE4))*180/PI()),IF((Koordinaten!$F$5-BD4)<0,0+(ATAN((Koordinaten!$F$5-BD4)/(Koordinaten!$F$6-BE4))*180/PI()))),IF((Koordinaten!$F$5-BD4)<0,180+(ATAN((Koordinaten!$F$5-BD4)/(Koordinaten!$F$6-BE4))*180/PI()),180+(ATAN((Koordinaten!$F$5-BD4)/(Koordinaten!$F$6-BE4))*180/PI()))) -> 100.28254 | BJ4: =BI4/360*6400 -> 1782.8006 | BK4: =BD4 -> 707 | BL4: =BE4+2 -> 434 | BM4: =((Koordinaten!$D$5-BK4)^2+(Koordinaten!$D$6-BL4)^2)^(1/2)*10 -> 2293.4036 | BN4: =VLOOKUP(Koordinaten!$E$12,Tabelle1!$G$4:$AB$8,16,FALSE) -> 1137.73 | BO4: =IF((Koordinaten!$D$7-Koordinaten!$E$7)>0,BN4+Koordinaten!$E$16,BN4-Koordinaten!$E$16) -> 1128.6163 | BP4: =IF((Koordinaten!$F$6-BL4)<0,IF((Koordinaten!$F$5-BK4)>0,360+(ATAN((Koordinaten!$F$5-BK4)/(Koordinaten!$F$6-BL4))*180/PI()),IF((Koordinaten!$F$5-BK4)<0,0+(ATAN((Koordinaten!$F$5-BK4)/(Koordinaten!$F$6-BL4))*180/PI()))),IF((Koordinaten!$F$5-BK4)<0,180+(ATAN((Koordinaten!$F$5-BK4)/(Koordinaten!$F$6-BL4))*180/PI()),180+(ATAN((Koordinaten!$F$5-BK4)/(Koordinaten!$F$6-BL4))*180/PI()))) -> 99.790897 | BQ4: =BP4/360*6400 -> 1774.0604 | BR4: =BK4 -> 707 | BS4: =BL4+2 -> 436 | BT4: =((Koordinaten!$D$5-BR4)^2+(Koordinaten!$D$6-BS4)^2)^(1/2)*10 -> 2290.0873 | BU4: =VLOOKUP(Koordinaten!$E$12,Tabelle1!$G$4:$AB$8,17,FALSE) -> 1138.6704 | BV4: =IF((Koordinaten!$D$7-Koordinaten!$E$7)>0,BU4+Koordinaten!$E$16,BU4-Koordinaten!$E$16) -> 1129.5567 | BW4: =IF((Koordinaten!$F$6-BS4)<0,IF((Koordinaten!$F$5-BR4)>0,360+(ATAN((Koordinaten!$F$5-BR4)/(Koordinaten!$F$6-BS4))*180/PI()),IF((Koordinaten!$F$5-BR4)<0,0+(ATAN((Koordinaten!$F$5-BR4)/(Koordinaten!$F$6-BS4))*180/PI()))),IF((Koordinaten!$F$5-BR4)<0,180+(ATAN((Koordinaten!$F$5-BR4)/(Koordinaten!$F$6-BS4))*180/PI()),180+(ATAN((Koordinaten!$F$5-BR4)/(Koordinaten!$F$6-BS4))*180/PI()))) -> 99.297798 | BX4: =BW4/360*6400 -> 1765.2942 | BY4: =BR4 -> 707 | BZ4: =BS4+2 -> 438 | CA4: =((Koordinaten!$D$5-BY4)^2+(Koordinaten!$D$6-BZ4)^2)^(1/2)*10 -> 2286.9412 | CB4: =VLOOKUP(Koordinaten!$E$12,Tabelle1!$G$4:$AB$8,18,FALSE) -> 1139.56 | CC4: =IF((Koordinaten!$D$7-Koordinaten!$E$7)>0,CB4+Koordinaten!$E$16,CB4-Koordinaten!$E$16) -> 1130.4463 | CD4: =IF((Koordinaten!$F$6-BZ4)<0,IF((Koordinaten!$F$5-BY4)>0,360+(ATAN((Koordinaten!$F$5-BY4)/(Koordinaten!$F$6-BZ4))*180/PI()),IF((Koordinaten!$F$5-BY4)<0,0+(ATAN((Koordinaten!$F$5-BY4)/(Koordinaten!$F$6-BZ4))*180/PI()))),IF((Koordinaten!$F$5-BY4)<0,180+(ATAN((Koordinaten!$F$5-BY4)/(Koordinaten!$F$6-BZ4))*180/PI()),180+(ATAN((Koordinaten!$F$5-BY4)/(Koordinaten!$F$6-BZ4))*180/PI()))) -> 98.803306 | CE4: =CD4/360*6400 -> 1756.5032 | CF4: =BY4 -> 707 | CG4: =BZ4+2 -> 440 | CH4: =((Koordinaten!$D$5-CF4)^2+(Koordinaten!$D$6-CG4)^2)^(1/2)*10 -> 2283.9658 | CI4: =VLOOKUP(Koordinaten!$E$12,Tabelle1!$G$4:$AB$8,19,FALSE) -> 1140.3991 | CJ4: =IF((Koordinaten!$D$7-Koordinaten!$E$7)>0,CI4+Koordinaten!$E$16,CI4-Koordinaten!$E$16) -> 1131.2854 | CK4: =IF((Koordinaten!$F$6-CG4)<0,IF((Koordinaten!$F$5-CF4)>0,360+(ATAN((Koordinaten!$F$5-CF4)/(Koordinaten!$F$6-CG4))*180/PI()),IF((Koordinaten!$F$5-CF4)<0,0+(ATAN((Koordinaten!$F$5-CF4)/(Koordinaten!$F$6-CG4))*180/PI()))),IF((Koordinaten!$F$5-CF4)<0,180+(ATAN((Koordinaten!$F$5-CF4)/(Koordinaten!$F$6-CG4))*180/PI()),180+(ATAN((Koordinaten!$F$5-CF4)/(Koordinaten!$F$6-CG4))*180/PI()))) -> 98.307488 | CL4: =CK4/360*6400 -> 1747.6887 | CM4: =CF4 -> 707 | CN4: =CG4+2 -> 442 | CO4: =((Koordinaten!$D$5-CM4)^2+(Koordinaten!$D$6-CN4)^2)^(1/2)*10 -> 2281.162 | CP4: =VLOOKUP(Koordinaten!$E$12,Tabelle1!$G$4:$AB$8,20,FALSE) -> 1141.1878 | CQ4: =IF((Koordinaten!$D$7-Koordinaten!$E$7)>0,CP4+Koordinaten!$E$16,CP4-Koordinaten!$E$16) -> 1132.0742 | CR4: =IF((Koordinaten!$F$6-CN4)<0,IF((Koordinaten!$F$5-CM4)>0,360+(ATAN((Koordinaten!$F$5-CM4)/(Koordinaten!$F$6-CN4))*180/PI()),IF((Koordinaten!$F$5-CM4)<0,0+(ATAN((Koordinaten!$F$5-CM4)/(Koordinaten!$F$6-CN4))*180/PI()))),IF((Koordinaten!$F$5-CM4)<0,180+(ATAN((Koordinaten!$F$5-CM4)/(Koordinaten!$F$6-CN4))*180/PI()),180+(ATAN((Koordinaten!$F$5-CM4)/(Koordinaten!$F$6-CN4))*180/PI()))) -> 97.810414 | CS4: =CR4/360*6400 -> 1738.8518 | CT4: =CM4 -> 707 | CU4: =CN4+2 -> 444 | CV4: =((Koordinaten!$D$5-CT4)^2+(Koordinaten!$D$6-CU4)^2)^(1/2)*10 -> 2278.5302 | CW4: =VLOOKUP(Koordinaten!$E$12,Tabelle1!$G$4:$AB$8,21,FALSE) -> 1141.9264 | CX4: =IF((Koordinaten!$D$7-Koordinaten!$E$7)>0,CW4+Koordinaten!$E$16,CW4-Koordinaten!$E$16) -> 1132.8128 | CY4: =IF((Koordinaten!$F$6-CU4)<0,IF((Koordinaten!$F$5-CT4)>0,360+(ATAN((Koordinaten!$F$5-CT4)/(Koordinaten!$F$6-CU4))*180/PI()),IF((Koordinaten!$F$5-CT4)<0,0+(ATAN((Koordinaten!$F$5-CT4)/(Koordinaten!$F$6-CU4))*180/PI()))),IF((Koordinaten!$F$5-CT4)<0,180+(ATAN((Koordinaten!$F$5-CT4)/(Koordinaten!$F$6-CU4))*180/PI()),180+(ATAN((Koordinaten!$F$5-CT4)/(Koordinaten!$F$6-CU4))*180/PI()))) -> 97.312155 | CZ4: =CY4/360*6400 -> 1729.9939 | DA4: =CT4 -> 707 | DB4: =CU4+2 -> 446 | DC4: =((Koordinaten!$D$5-DA4)^2+(Koordinaten!$D$6-DB4)^2)^(1/2)*10 -> 2276.0712 | DD4: =VLOOKUP(Koordinaten!$E$12,Tabelle1!$G$4:$AB$8,22,FALSE) -> 1142.6151 | DE4: =IF((Koordinaten!$D$7-Koordinaten!$E$7)>0,DD4+Koordinaten!$E$16,DD4-Koordinaten!$E$16) -> 1133.5014 | DF4: =IF((Koordinaten!$F$6-DB4)<0,IF((Koordinaten!$F$5-DA4)>0,360+(ATAN((Koordinaten!$F$5-DA4)/(Koordinaten!$F$6-DB4))*180/PI()),IF((Koordinaten!$F$5-DA4)<0,0+(ATAN((Koordinaten!$F$5-DA4)/(Koordinaten!$F$6-DB4))*180/PI()))),IF((Koordinaten!$F$5-DA4)<0,180+(ATAN((Koordinaten!$F$5-DA4)/(Koordinaten!$F$6-DB4))*180/PI()),180+(ATAN((Koordinaten!$F$5-DA4)/(Koordinaten!$F$6-DB4))*180/PI()))) -> 96.812781 | DG4: =DF4/360*6400 -> 1721.1161
F5: mil - 1 Ring | G5: 1 | H5: =Koordinaten!$E$14 -> 2304.3654 | I5: =Tabelle1!$AY$4 -> 2300.5434 | J5: =Tabelle1!$BF$4 -> 2296.8892 | K5: =Tabelle1!$BM$4 -> 2293.4036 | L5: =Tabelle1!$BT$4 -> 2290.0873 | M5: =Tabelle1!$CA$4 -> 2286.9412 | N5: =Tabelle1!$CH$4 -> 2283.9658 | O5: =Tabelle1!$CO$4 -> 2281.162 | P5: =Tabelle1!$CV$4 -> 2278.5302 | Q5: =Tabelle1!$DC$4 -> 2276.0712 | R5: =IF(H5>900, "n.M.",S5) -> n.M. | S5: =$AG$5*H5^4+$AF$5*H5^3+$AE$5*H5^2+$AD$5*H5+$AC$5 -> -19398.158 | T5: =$AG$5*I5^4+$AF$5*I5^3+$AE$5*I5^2+$AD$5*I5+$AC$5 -> -19241.941 | U5: =$AG$5*J5^4+$AF$5*J5^3+$AE$5*J5^2+$AD$5*J5+$AC$5 -> -19093.431 | V5: =$AG$5*K5^4+$AF$5*K5^3+$AE$5*K5^2+$AD$5*K5+$AC$5 -> -18952.544 | W5: =$AG$5*L5^4+$AF$5*L5^3+$AE$5*L5^2+$AD$5*L5+$AC$5 -> -18819.198 | X5: =$AG$5*M5^4+$AF$5*M5^3+$AE$5*M5^2+$AD$5*M5+$AC$5 -> -18693.318 | Y5: =$AG$5*N5^4+$AF$5*N5^3+$AE$5*N5^2+$AD$5*N5+$AC$5 -> -18574.829 | Z5: =$AG$5*O5^4+$AF$5*O5^3+$AE$5*O5^2+$AD$5*O5+$AC$5 -> -18463.665 | ... AB5: =$AG$5*Q5^4+$AF$5*Q5^3+$AE$5*Q5^2+$AD$5*Q5+$AC$5 -> -18263.053 | AC5: 1585.33 | AD5: =-0.294365 -> -0.294365 | AE5: =-0.00115982 -> -0.00115982 | AF5: =0.00000203322 -> 2.03322e-06 | AG5: =-0.00000000138403 -> -1.38403e-09
F6: mil - 2 Ringe | G6: 2 | H6: =Koordinaten!$E$14 -> 2304.3654 | I6: =Tabelle1!$AY$4 -> 2300.5434 | J6: =Tabelle1!$BF$4 -> 2296.8892 | K6: =Tabelle1!$BM$4 -> 2293.4036 | L6: =Tabelle1!$BT$4 -> 2290.0873 | M6: =Tabelle1!$CA$4 -> 2286.9412 | N6: =Tabelle1!$CH$4 -> 2283.9658 | O6: =Tabelle1!$CO$4 -> 2281.162 | P6: =Tabelle1!$CV$4 -> 2278.5302 | Q6: =Tabelle1!$DC$4 -> 2276.0712 | R6: =IF(H6>1600, "n.M.",S6) -> n.M. | S6: =$AH$6*H6^5+$AG$6*H6^4+$AF$6*H6^3+$AE$6*H6^2+$AD$6*H6+$AC$6 -> -1585.8487 | T6: =$AH$6*I6^5+$AG$6*I6^4+$AF$6*I6^3+$AE$6*I6^2+$AD$6*I6+$AC$6 -> -1555.6314 | U6: =$AH$6*J6^5+$AG$6*J6^4+$AF$6*J6^3+$AE$6*J6^2+$AD$6*J6+$AC$6 -> -1527.0062 | V6: =$AH$6*K6^5+$AG$6*K6^4+$AF$6*K6^3+$AE$6*K6^2+$AD$6*K6+$AC$6 -> -1499.942 | W6: =$AH$6*L6^5+$AG$6*L6^4+$AF$6*L6^3+$AE$6*L6^2+$AD$6*L6+$AC$6 -> -1474.4092 | X6: =$AH$6*M6^5+$AG$6*M6^4+$AF$6*M6^3+$AE$6*M6^2+$AD$6*M6+$AC$6 -> -1450.3796 | Y6: =$AH$6*N6^5+$AG$6*N6^4+$AF$6*N6^3+$AE$6*N6^2+$AD$6*N6+$AC$6 -> -1427.8271 | Z6: =$AH$6*O6^5+$AG$6*O6^4+$AF$6*O6^3+$AE$6*O6^2+$AD$6*O6+$AC$6 -> -1406.7268 | ... AB6: =$AH$6*Q6^5+$AG$6*Q6^4+$AF$6*Q6^3+$AE$6*Q6^2+$AD$6*Q6+$AC$6 -> -1368.7917 | AC6: 1628.85 | AD6: =-0.590671 -> -0.590671 | AE6: 0.000957662 | AF6: -1.4732e-06 | AG6: 1.00979e-09 | AH6: =-0.000000000000267564 -> -2.67564e-13 | AN6: 2 | AO6: NE | AP6: =Koordinaten!$E$5 -> 707 | AQ6: =Koordinaten!$E$6 -> 428 | AR6: =((Koordinaten!$D$5-AP6)^2+(Koordinaten!$D$6-AQ6)^2)^(1/2)*10 -> 2304.3654 | AS6: =VLOOKUP(Koordinaten!$E$12,Tabelle1!$G$4:$AB$8,13,FALSE) -> 1134.6016 | AT6: =IF((Koordinaten!$D$7-Koordinaten!$E$7)>0,AS6+Koordinaten!$E$16,AS6-Koordinaten!$E$16) -> 1125.488 | AU6: =IF((Koordinaten!$F$6-AQ6)<0,IF((Koordinaten!$F$5-AP6)>0,360+(ATAN((Koordinaten!$F$5-AP6)/(Koordinaten!$F$6-AQ6))*180/PI()),IF((Koordinaten!$F$5-AP6)<0,0+(ATAN((Koordinaten!$F$5-AP6)/(Koordinaten!$F$6-AQ6))*180/PI()))),IF((Koordinaten!$F$5-AP6)<0,180+(ATAN((Koordinaten!$F$5-AP6)/(Koordinaten!$F$6-AQ6))*180/PI()),180+(ATAN((Koordinaten!$F$5-AP6)/(Koordinaten!$F$6-AQ6))*180/PI()))) -> 101.26117 | AV6: =AU6/360*6400 -> 1800.1986 | AW6: =AP6+1.414 -> 708.414 | AX6: =AQ6+1.414 -> 429.414 | AY6: =((Koordinaten!$D$5-AW6)^2+(Koordinaten!$D$6-AX6)^2)^(1/2)*10 -> 2315.5316 | AZ6: =VLOOKUP(Koordinaten!$E$12,Tabelle1!$G$4:$AB$8,14,FALSE) -> 1135.6959 | BA6: =IF((Koordinaten!$D$7-Koordinaten!$E$7)>0,AZ6+Koordinaten!$E$16,AZ6-Koordinaten!$E$16) -> 1126.5822 | BB6: =IF((Koordinaten!$F$6-AX6)<0,IF((Koordinaten!$F$5-AW6)>0,360+(ATAN((Koordinaten!$F$5-AW6)/(Koordinaten!$F$6-AX6))*180/PI()),IF((Koordinaten!$F$5-AW6)<0,0+(ATAN((Koordinaten!$F$5-AW6)/(Koordinaten!$F$6-AX6))*180/PI()))),IF((Koordinaten!$F$5-AW6)<0,180+(ATAN((Koordinaten!$F$5-AW6)/(Koordinaten!$F$6-AX6))*180/PI()),180+(ATAN((Koordinaten!$F$5-AW6)/(Koordinaten!$F$6-AX6))*180/PI()))) -> 100.8497 | BC6: =BB6/360*6400 -> 1792.8835 | BD6: =AW6+1.414 -> 709.828 | BE6: =AX6+1.414 -> 430.828 | BF6: =((Koordinaten!$D$5-BD6)^2+(Koordinaten!$D$6-BE6)^2)^(1/2)*10 -> 2326.8161 | BG6: =VLOOKUP(Koordinaten!$E$12,Tabelle1!$G$4:$AB$8,15,FALSE) -> 1136.7386 | BH6: =IF((Koordinaten!$D$7-Koordinaten!$E$7)>0,BG6+Koordinaten!$E$16,BG6-Koordinaten!$E$16) -> 1127.6249 | BI6: =IF((Koordinaten!$F$6-BE6)<0,IF((Koordinaten!$F$5-BD6)>0,360+(ATAN((Koordinaten!$F$5-BD6)/(Koordinaten!$F$6-BE6))*180/PI()),IF((Koordinaten!$F$5-BD6)<0,0+(ATAN((Koordinaten!$F$5-BD6)/(Koordinaten!$F$6-BE6))*180/PI()))),IF((Koordinaten!$F$5-BD6)<0,180+(ATAN((Koordinaten!$F$5-BD6)/(Koordinaten!$F$6-BE6))*180/PI()),180+(ATAN((Koordinaten!$F$5-BD6)/(Koordinaten!$F$6-BE6))*180/PI()))) -> 100.44219 | BJ6: =BI6/360*6400 -> 1785.639 | BK6: =BD6+1.414 -> 711.242 | BL6: =BE6+1.414 -> 432.242 | BM6: =((Koordinaten!$D$5-BK6)^2+(Koordinaten!$D$6-BL6)^2)^(1/2)*10 -> 2338.2171 | BN6: =VLOOKUP(Koordinaten!$E$12,Tabelle1!$G$4:$AB$8,16,FALSE) -> 1137.73 | BO6: =IF((Koordinaten!$D$7-Koordinaten!$E$7)>0,BN6+Koordinaten!$E$16,BN6-Koordinaten!$E$16) -> 1128.6163 | BP6: =IF((Koordinaten!$F$6-BL6)<0,IF((Koordinaten!$F$5-BK6)>0,360+(ATAN((Koordinaten!$F$5-BK6)/(Koordinaten!$F$6-BL6))*180/PI()),IF((Koordinaten!$F$5-BK6)<0,0+(ATAN((Koordinaten!$F$5-BK6)/(Koordinaten!$F$6-BL6))*180/PI()))),IF((Koordinaten!$F$5-BK6)<0,180+(ATAN((Koordinaten!$F$5-BK6)/(Koordinaten!$F$6-BL6))*180/PI()),180+(ATAN((Koordinaten!$F$5-BK6)/(Koordinaten!$F$6-BL6))*180/PI()))) -> 100.03864 | BQ6: =BP6/360*6400 -> 1778.4647 | BR6: =BK6+1.414 -> 712.656 | BS6: =BL6+1.414 -> 433.656 | BT6: =((Koordinaten!$D$5-BR6)^2+(Koordinaten!$D$6-BS6)^2)^(1/2)*10 -> 2349.733 | BU6: =VLOOKUP(Koordinaten!$E$12,Tabelle1!$G$4:$AB$8,17,FALSE) -> 1138.6704 | BV6: =IF((Koordinaten!$D$7-Koordinaten!$E$7)>0,BU6+Koordinaten!$E$16,BU6-Koordinaten!$E$16) -> 1129.5567 | BW6: =IF((Koordinaten!$F$6-BS6)<0,IF((Koordinaten!$F$5-BR6)>0,360+(ATAN((Koordinaten!$F$5-BR6)/(Koordinaten!$F$6-BS6))*180/PI()),IF((Koordinaten!$F$5-BR6)<0,0+(ATAN((Koordinaten!$F$5-BR6)/(Koordinaten!$F$6-BS6))*180/PI()))),IF((Koordinaten!$F$5-BR6)<0,180+(ATAN((Koordinaten!$F$5-BR6)/(Koordinaten!$F$6-BS6))*180/PI()),180+(ATAN((Koordinaten!$F$5-BR6)/(Koordinaten!$F$6-BS6))*180/PI()))) -> 99.639026 | BX6: =BW6/360*6400 -> 1771.3605 | BY6: =BR6+1.414 -> 714.07 | BZ6: =BS6+1.414 -> 435.07 | CA6: =((Koordinaten!$D$5-BY6)^2+(Koordinaten!$D$6-BZ6)^2)^(1/2)*10 -> 2361.3621 | CB6: =VLOOKUP(Koordinaten!$E$12,Tabelle1!$G$4:$AB$8,18,FALSE) -> 1139.56 | CC6: =IF((Koordinaten!$D$7-Koordinaten!$E$7)>0,CB6+Koordinaten!$E$16,CB6-Koordinaten!$E$16) -> 1130.4463 | CD6: =IF((Koordinaten!$F$6-BZ6)<0,IF((Koordinaten!$F$5-BY6)>0,360+(ATAN((Koordinaten!$F$5-BY6)/(Koordinaten!$F$6-BZ6))*180/PI()),IF((Koordinaten!$F$5-BY6)<0,0+(ATAN((Koordinaten!$F$5-BY6)/(Koordinaten!$F$6-BZ6))*180/PI()))),IF((Koordinaten!$F$5-BY6)<0,180+(ATAN((Koordinaten!$F$5-BY6)/(Koordinaten!$F$6-BZ6))*180/PI()),180+(ATAN((Koordinaten!$F$5-BY6)/(Koordinaten!$F$6-BZ6))*180/PI()))) -> 99.243328 | CE6: =CD6/360*6400 -> 1764.3258 | CF6: =BY6+1.414 -> 715.484 | CG6: =BZ6+1.414 -> 436.484 | CH6: =((Koordinaten!$D$5-CF6)^2+(Koordinaten!$D$6-CG6)^2)^(1/2)*10 -> 2373.1027 | CI6: =VLOOKUP(Koordinaten!$E$12,Tabelle1!$G$4:$AB$8,19,FALSE) -> 1140.3991 | CJ6: =IF((Koordinaten!$D$7-Koordinaten!$E$7)>0,CI6+Koordinaten!$E$16,CI6-Koordinaten!$E$16) -> 1131.2854 | CK6: =IF((Koordinaten!$F$6-CG6)<0,IF((Koordinaten!$F$5-CF6)>0,360+(ATAN((Koordinaten!$F$5-CF6)/(Koordinaten!$F$6-CG6))*180/PI()),IF((Koordinaten!$F$5-CF6)<0,0+(ATAN((Koordinaten!$F$5-CF6)/(Koordinaten!$F$6-CG6))*180/PI()))),IF((Koordinaten!$F$5-CF6)<0,180+(ATAN((Koordinaten!$F$5-CF6)/(Koordinaten!$F$6-CG6))*180/PI()),180+(ATAN((Koordinaten!$F$5-CF6)/(Koordinaten!$F$6-CG6))*180/PI()))) -> 98.851527 | CL6: =CK6/360*6400 -> 1757.3605 | CM6: =CF6+1.414 -> 716.898 | CN6: =CG6+1.414 -> 437.898 | CO6: =((Koordinaten!$D$5-CM6)^2+(Koordinaten!$D$6-CN6)^2)^(1/2)*10 -> 2384.9532 | CP6: =VLOOKUP(Koordinaten!$E$12,Tabelle1!$G$4:$AB$8,20,FALSE) -> 1141.1878 | CQ6: =IF((Koordinaten!$D$7-Koordinaten!$E$7)>0,CP6+Koordinaten!$E$16,CP6-Koordinaten!$E$16) -> 1132.0742 | CR6: =IF((Koordinaten!$F$6-CN6)<0,IF((Koordinaten!$F$5-CM6)>0,360+(ATAN((Koordinaten!$F$5-CM6)/(Koordinaten!$F$6-CN6))*180/PI()),IF((Koordinaten!$F$5-CM6)<0,0+(ATAN((Koordinaten!$F$5-CM6)/(Koordinaten!$F$6-CN6))*180/PI()))),IF((Koordinaten!$F$5-CM6)<0,180+(ATAN((Koordinaten!$F$5-CM6)/(Koordinaten!$F$6-CN6))*180/PI()),180+(ATAN((Koordinaten!$F$5-CM6)/(Koordinaten!$F$6-CN6))*180/PI()))) -> 98.463602 | CS6: =CR6/360*6400 -> 1750.464 | CT6: =CM6+1.414 -> 718.312 | CU6: =CN6+1.414 -> 439.312 | CV6: =((Koordinaten!$D$5-CT6)^2+(Koordinaten!$D$6-CU6)^2)^(1/2)*10 -> 2396.9119 | CW6: =VLOOKUP(Koordinaten!$E$12,Tabelle1!$G$4:$AB$8,21,FALSE) -> 1141.9264 | CX6: =IF((Koordinaten!$D$7-Koordinaten!$E$7)>0,CW6+Koordinaten!$E$16,CW6-Koordinaten!$E$16) -> 1132.8128 | CY6: =IF((Koordinaten!$F$6-CU6)<0,IF((Koordinaten!$F$5-CT6)>0,360+(ATAN((Koordinaten!$F$5-CT6)/(Koordinaten!$F$6-CU6))*180/PI()),IF((Koordinaten!$F$5-CT6)<0,0+(ATAN((Koordinaten!$F$5-CT6)/(Koordinaten!$F$6-CU6))*180/PI()))),IF((Koordinaten!$F$5-CT6)<0,180+(ATAN((Koordinaten!$F$5-CT6)/(Koordinaten!$F$6-CU6))*180/PI()),180+(ATAN((Koordinaten!$F$5-CT6)/(Koordinaten!$F$6-CU6))*180/PI()))) -> 98.07953 | CZ6: =CY6/360*6400 -> 1743.6361 | DA6: =CT6+1.414 -> 719.726 | DB6: =CU6+1.414 -> 440.726 | DC6: =((Koordinaten!$D$5-DA6)^2+(Koordinaten!$D$6-DB6)^2)^(1/2)*10 -> 2408.9773 | DD6: =VLOOKUP(Koordinaten!$E$12,Tabelle1!$G$4:$AB$8,22,FALSE) -> 1142.6151 | DE6: =IF((Koordinaten!$D$7-Koordinaten!$E$7)>0,DD6+Koordinaten!$E$16,DD6-Koordinaten!$E$16) -> 1133.5014 | DF6: =IF((Koordinaten!$F$6-DB6)<0,IF((Koordinaten!$F$5-DA6)>0,360+(ATAN((Koordinaten!$F$5-DA6)/(Koordinaten!$F$6-DB6))*180/PI()),IF((Koordinaten!$F$5-DA6)<0,0+(ATAN((Koordinaten!$F$5-DA6)/(Koordinaten!$F$6-DB6))*180/PI()))),IF((Koordinaten!$F$5-DA6)<0,180+(ATAN((Koordinaten!$F$5-DA6)/(Koordinaten!$F$6-DB6))*180/PI()),180+(ATAN((Koordinaten!$F$5-DA6)/(Koordinaten!$F$6-DB6))*180/PI()))) -> 97.699288 | DG6: =DF6/360*6400 -> 1736.8762
F7: mil - 3 Ringe | G7: 3 | H7: =Koordinaten!$E$14 -> 2304.3654 | I7: =Tabelle1!$AY$4 -> 2300.5434 | J7: =Tabelle1!$BF$4 -> 2296.8892 | K7: =Tabelle1!$BM$4 -> 2293.4036 | L7: =Tabelle1!$BT$4 -> 2290.0873 | M7: =Tabelle1!$CA$4 -> 2286.9412 | N7: =Tabelle1!$CH$4 -> 2283.9658 | O7: =Tabelle1!$CO$4 -> 2281.162 | P7: =Tabelle1!$CV$4 -> 2278.5302 | Q7: =Tabelle1!$DC$4 -> 2276.0712 | R7: =IF(H7>2300, "n.M.",S7) -> n.M. | S7: =$AH$7*H7^5+$AG$7*H7^4+$AF$7*H7^3+$AE$7*H7^2+$AD$7*H7+$AC$7 -> 804.59793 | T7: =$AH$7*I7^5+$AG$7*I7^4+$AF$7*I7^3+$AE$7*I7^2+$AD$7*I7+$AC$7 -> 809.33372 | U7: =$AH$7*J7^5+$AG$7*J7^4+$AF$7*J7^3+$AE$7*J7^2+$AD$7*J7+$AC$7 -> 813.81135 | V7: =$AH$7*K7^5+$AG$7*K7^4+$AF$7*K7^3+$AE$7*K7^2+$AD$7*K7+$AC$7 -> 818.03709 | W7: =$AH$7*L7^5+$AG$7*L7^4+$AF$7*L7^3+$AE$7*L7^2+$AD$7*L7+$AC$7 -> 822.01684 | X7: =$AH$7*M7^5+$AG$7*M7^4+$AF$7*M7^3+$AE$7*M7^2+$AD$7*M7+$AC$7 -> 825.75615 | Y7: =$AH$7*N7^5+$AG$7*N7^4+$AF$7*N7^3+$AE$7*N7^2+$AD$7*N7+$AC$7 -> 829.26022 | Z7: =$AH$7*O7^5+$AG$7*O7^4+$AF$7*O7^3+$AE$7*O7^2+$AD$7*O7+$AC$7 -> 832.53393 | ... AB7: =$AH$7*Q7^5+$AG$7*Q7^4+$AF$7*Q7^3+$AE$7*Q7^2+$AD$7*Q7+$AC$7 -> 838.40803 | AC7: 1710.15 | AD7: =-0.931423 -> -0.931423 | AE7: 0.00161641 | AF7: =-0.00000166008 -> -1.66008e-06 | AG7: 7.73346e-10 | AH7: =-0.000000000000135976 -> -1.35976e-13
F8: mil - 4 Ringe | G8: 4 | H8: =Koordinaten!$E$14 -> 2304.3654 | I8: =Tabelle1!$AY$4 -> 2300.5434 | J8: =Tabelle1!$BF$4 -> 2296.8892 | K8: =Tabelle1!$BM$4 -> 2293.4036 | L8: =Tabelle1!$BT$4 -> 2290.0873 | M8: =Tabelle1!$CA$4 -> 2286.9412 | N8: =Tabelle1!$CH$4 -> 2283.9658 | O8: =Tabelle1!$CO$4 -> 2281.162 | P8: =Tabelle1!$CV$4 -> 2278.5302 | Q8: =Tabelle1!$DC$4 -> 2276.0712 | R8: =IF(H8>2900, "n.M.",S8) -> 1134.6016 | S8: =$AH$8*H8^5+$AG$8*H8^4+$AF$8*H8^3+$AE$8*H8^2+$AD$8*H8+$AC$8 -> 1134.6016 | T8: =$AH$8*I8^5+$AG$8*I8^4+$AF$8*I8^3+$AE$8*I8^2+$AD$8*I8+$AC$8 -> 1135.6959 | U8: =$AH$8*J8^5+$AG$8*J8^4+$AF$8*J8^3+$AE$8*J8^2+$AD$8*J8+$AC$8 -> 1136.7386 | V8: =$AH$8*K8^5+$AG$8*K8^4+$AF$8*K8^3+$AE$8*K8^2+$AD$8*K8+$AC$8 -> 1137.73 | W8: =$AH$8*L8^5+$AG$8*L8^4+$AF$8*L8^3+$AE$8*L8^2+$AD$8*L8+$AC$8 -> 1138.6704 | X8: =$AH$8*M8^5+$AG$8*M8^4+$AF$8*M8^3+$AE$8*M8^2+$AD$8*M8+$AC$8 -> 1139.56 | Y8: =$AH$8*N8^5+$AG$8*N8^4+$AF$8*N8^3+$AE$8*N8^2+$AD$8*N8+$AC$8 -> 1140.3991 | Z8: =$AH$8*O8^5+$AG$8*O8^4+$AF$8*O8^3+$AE$8*O8^2+$AD$8*O8+$AC$8 -> 1141.1878 | ... AB8: =$AH$8*Q8^5+$AG$8*Q8^4+$AF$8*Q8^3+$AE$8*Q8^2+$AD$8*Q8+$AC$8 -> 1142.6151 | AC8: 1652.31 | AD8: =-0.430979 -> -0.430979 | AE8: 0.000459345 | AF8: =-0.000000374758 -> -3.74758e-07 | AG8: 1.38268e-10 | AH8: =-0.0000000000000196504 -> -1.96504e-14 | AN8: 3 | AO8: E | AP8: =Koordinaten!$E$5 -> 707 | AQ8: =Koordinaten!$E$6 -> 428 | AR8: =((Koordinaten!$D$5-AP8)^2+(Koordinaten!$D$6-AQ8)^2)^(1/2)*10 -> 2304.3654 | AS8: =VLOOKUP(Koordinaten!$E$12,Tabelle1!$G$4:$AB$8,13,FALSE) -> 1134.6016 | AT8: =IF((Koordinaten!$D$7-Koordinaten!$E$7)>0,AS8+Koordinaten!$E$16,AS8-Koordinaten!$E$16) -> 1125.488 | AU8: =IF((Koordinaten!$F$6-AQ8)<0,IF((Koordinaten!$F$5-AP8)>0,360+(ATAN((Koordinaten!$F$5-AP8)/(Koordinaten!$F$6-AQ8))*180/PI()),IF((Koordinaten!$F$5-AP8)<0,0+(ATAN((Koordinaten!$F$5-AP8)/(Koordinaten!$F$6-AQ8))*180/PI()))),IF((Koordinaten!$F$5-AP8)<0,180+(ATAN((Koordinaten!$F$5-AP8)/(Koordinaten!$F$6-AQ8))*180/PI()),180+(ATAN((Koordinaten!$F$5-AP8)/(Koordinaten!$F$6-AQ8))*180/PI()))) -> 101.26117 | AV8: =AU8/360*6400 -> 1800.1986 | AW8: =AP8+2 -> 709 | AX8: =AQ8 -> 428 | AY8: =((Koordinaten!$D$5-AW8)^2+(Koordinaten!$D$6-AX8)^2)^(1/2)*10 -> 2323.9836 | AZ8: =VLOOKUP(Koordinaten!$E$12,Tabelle1!$G$4:$AB$8,14,FALSE) -> 1135.6959 | BA8: =IF((Koordinaten!$D$7-Koordinaten!$E$7)>0,AZ8+Koordinaten!$E$16,AZ8-Koordinaten!$E$16) -> 1126.5822 | BB8: =IF((Koordinaten!$F$6-AX8)<0,IF((Koordinaten!$F$5-AW8)>0,360+(ATAN((Koordinaten!$F$5-AW8)/(Koordinaten!$F$6-AX8))*180/PI()),IF((Koordinaten!$F$5-AW8)<0,0+(ATAN((Koordinaten!$F$5-AW8)/(Koordinaten!$F$6-AX8))*180/PI()))),IF((Koordinaten!$F$5-AW8)<0,180+(ATAN((Koordinaten!$F$5-AW8)/(Koordinaten!$F$6-AX8))*180/PI()),180+(ATAN((Koordinaten!$F$5-AW8)/(Koordinaten!$F$6-AX8))*180/PI()))) -> 101.16488 | BC8: =BB8/360*6400 -> 1798.4868 | BD8: =AW8+2 -> 711 | BE8: =AX8 -> 428 | BF8: =((Koordinaten!$D$5-BD8)^2+(Koordinaten!$D$6-BE8)^2)^(1/2)*10 -> 2343.6083 | BG8: =VLOOKUP(Koordinaten!$E$12,Tabelle1!$G$4:$AB$8,15,FALSE) -> 1136.7386 | BH8: =IF((Koordinaten!$D$7-Koordinaten!$E$7)>0,BG8+Koordinaten!$E$16,BG8-Koordinaten!$E$16) -> 1127.6249 | BI8: =IF((Koordinaten!$F$6-BE8)<0,IF((Koordinaten!$F$5-BD8)>0,360+(ATAN((Koordinaten!$F$5-BD8)/(Koordinaten!$F$6-BE8))*180/PI()),IF((Koordinaten!$F$5-BD8)<0,0+(ATAN((Koordinaten!$F$5-BD8)/(Koordinaten!$F$6-BE8))*180/PI()))),IF((Koordinaten!$F$5-BD8)<0,180+(ATAN((Koordinaten!$F$5-BD8)/(Koordinaten!$F$6-BE8))*180/PI()),180+(ATAN((Koordinaten!$F$5-BD8)/(Koordinaten!$F$6-BE8))*180/PI()))) -> 101.0702 | BJ8: =BI8/360*6400 -> 1796.8036 | BK8: =BD8+2 -> 713 | BL8: =BE8 -> 428 | BM8: =((Koordinaten!$D$5-BK8)^2+(Koordinaten!$D$6-BL8)^2)^(1/2)*10 -> 2363.2393 | BN8: =VLOOKUP(Koordinaten!$E$12,Tabelle1!$G$4:$AB$8,16,FALSE) -> 1137.73 | BO8: =IF((Koordinaten!$D$7-Koordinaten!$E$7)>0,BN8+Koordinaten!$E$16,BN8-Koordinaten!$E$16) -> 1128.6163 | BP8: =IF((Koordinaten!$F$6-BL8)<0,IF((Koordinaten!$F$5-BK8)>0,360+(ATAN((Koordinaten!$F$5-BK8)/(Koordinaten!$F$6-BL8))*180/PI()),IF((Koordinaten!$F$5-BK8)<0,0+(ATAN((Koordinaten!$F$5-BK8)/(Koordinaten!$F$6-BL8))*180/PI()))),IF((Koordinaten!$F$5-BK8)<0,180+(ATAN((Koordinaten!$F$5-BK8)/(Koordinaten!$F$6-BL8))*180/PI()),180+(ATAN((Koordinaten!$F$5-BK8)/(Koordinaten!$F$6-BL8))*180/PI()))) -> 100.9771 | BQ8: =BP8/360*6400 -> 1795.1484 | BR8: =BK8+2 -> 715 | BS8: =BL8 -> 428 | BT8: =((Koordinaten!$D$5-BR8)^2+(Koordinaten!$D$6-BS8)^2)^(1/2)*10 -> 2382.8764 | BU8: =VLOOKUP(Koordinaten!$E$12,Tabelle1!$G$4:$AB$8,17,FALSE) -> 1138.6704 | BV8: =IF((Koordinaten!$D$7-Koordinaten!$E$7)>0,BU8+Koordinaten!$E$16,BU8-Koordinaten!$E$16) -> 1129.5567 | BW8: =IF((Koordinaten!$F$6-BS8)<0,IF((Koordinaten!$F$5-BR8)>0,360+(ATAN((Koordinaten!$F$5-BR8)/(Koordinaten!$F$6-BS8))*180/PI()),IF((Koordinaten!$F$5-BR8)<0,0+(ATAN((Koordinaten!$F$5-BR8)/(Koordinaten!$F$6-BS8))*180/PI()))),IF((Koordinaten!$F$5-BR8)<0,180+(ATAN((Koordinaten!$F$5-BR8)/(Koordinaten!$F$6-BS8))*180/PI()),180+(ATAN((Koordinaten!$F$5-BR8)/(Koordinaten!$F$6-BS8))*180/PI()))) -> 100.88553 | BX8: =BW8/360*6400 -> 1793.5205 | BY8: =BR8+2 -> 717 | BZ8: =BS8 -> 428 | CA8: =((Koordinaten!$D$5-BY8)^2+(Koordinaten!$D$6-BZ8)^2)^(1/2)*10 -> 2402.5195 | CB8: =VLOOKUP(Koordinaten!$E$12,Tabelle1!$G$4:$AB$8,18,FALSE) -> 1139.56 | CC8: =IF((Koordinaten!$D$7-Koordinaten!$E$7)>0,CB8+Koordinaten!$E$16,CB8-Koordinaten!$E$16) -> 1130.4463 | CD8: =IF((Koordinaten!$F$6-BZ8)<0,IF((Koordinaten!$F$5-BY8)>0,360+(ATAN((Koordinaten!$F$5-BY8)/(Koordinaten!$F$6-BZ8))*180/PI()),IF((Koordinaten!$F$5-BY8)<0,0+(ATAN((Koordinaten!$F$5-BY8)/(Koordinaten!$F$6-BZ8))*180/PI()))),IF((Koordinaten!$F$5-BY8)<0,180+(ATAN((Koordinaten!$F$5-BY8)/(Koordinaten!$F$6-BZ8))*180/PI()),180+(ATAN((Koordinaten!$F$5-BY8)/(Koordinaten!$F$6-BZ8))*180/PI()))) -> 100.79545 | CE8: =CD8/360*6400 -> 1791.9192 | CF8: =BY8+2 -> 719 | CG8: =BZ8 -> 428 | CH8: =((Koordinaten!$D$5-CF8)^2+(Koordinaten!$D$6-CG8)^2)^(1/2)*10 -> 2422.1684 | CI8: =VLOOKUP(Koordinaten!$E$12,Tabelle1!$G$4:$AB$8,19,FALSE) -> 1140.3991 | CJ8: =IF((Koordinaten!$D$7-Koordinaten!$E$7)>0,CI8+Koordinaten!$E$16,CI8-Koordinaten!$E$16) -> 1131.2854 | CK8: =IF((Koordinaten!$F$6-CG8)<0,IF((Koordinaten!$F$5-CF8)>0,360+(ATAN((Koordinaten!$F$5-CF8)/(Koordinaten!$F$6-CG8))*180/PI()),IF((Koordinaten!$F$5-CF8)<0,0+(ATAN((Koordinaten!$F$5-CF8)/(Koordinaten!$F$6-CG8))*180/PI()))),IF((Koordinaten!$F$5-CF8)<0,180+(ATAN((Koordinaten!$F$5-CF8)/(Koordinaten!$F$6-CG8))*180/PI()),180+(ATAN((Koordinaten!$F$5-CF8)/(Koordinaten!$F$6-CG8))*180/PI()))) -> 100.70684 | CL8: =CK8/360*6400 -> 1790.3438 | CM8: =CF8+2 -> 721 | CN8: =CG8 -> 428 | CO8: =((Koordinaten!$D$5-CM8)^2+(Koordinaten!$D$6-CN8)^2)^(1/2)*10 -> 2441.8231 | CP8: =VLOOKUP(Koordinaten!$E$12,Tabelle1!$G$4:$AB$8,20,FALSE) -> 1141.1878 | CQ8: =IF((Koordinaten!$D$7-Koordinaten!$E$7)>0,CP8+Koordinaten!$E$16,CP8-Koordinaten!$E$16) -> 1132.0742 | CR8: =IF((Koordinaten!$F$6-CN8)<0,IF((Koordinaten!$F$5-CM8)>0,360+(ATAN((Koordinaten!$F$5-CM8)/(Koordinaten!$F$6-CN8))*180/PI()),IF((Koordinaten!$F$5-CM8)<0,0+(ATAN((Koordinaten!$F$5-CM8)/(Koordinaten!$F$6-CN8))*180/PI()))),IF((Koordinaten!$F$5-CM8)<0,180+(ATAN((Koordinaten!$F$5-CM8)/(Koordinaten!$F$6-CN8))*180/PI()),180+(ATAN((Koordinaten!$F$5-CM8)/(Koordinaten!$F$6-CN8))*180/PI()))) -> 100.61966 | CS8: =CR8/360*6400 -> 1788.7939 | CT8: =CM8+2 -> 723 | CU8: =CN8 -> 428 | CV8: =((Koordinaten!$D$5-CT8)^2+(Koordinaten!$D$6-CU8)^2)^(1/2)*10 -> 2461.4833 | CW8: =VLOOKUP(Koordinaten!$E$12,Tabelle1!$G$4:$AB$8,21,FALSE) -> 1141.9264 | CX8: =IF((Koordinaten!$D$7-Koordinaten!$E$7)>0,CW8+Koordinaten!$E$16,CW8-Koordinaten!$E$16) -> 1132.8128 | CY8: =IF((Koordinaten!$F$6-CU8)<0,IF((Koordinaten!$F$5-CT8)>0,360+(ATAN((Koordinaten!$F$5-CT8)/(Koordinaten!$F$6-CU8))*180/PI()),IF((Koordinaten!$F$5-CT8)<0,0+(ATAN((Koordinaten!$F$5-CT8)/(Koordinaten!$F$6-CU8))*180/PI()))),IF((Koordinaten!$F$5-CT8)<0,180+(ATAN((Koordinaten!$F$5-CT8)/(Koordinaten!$F$6-CU8))*180/PI()),180+(ATAN((Koordinaten!$F$5-CT8)/(Koordinaten!$F$6-CU8))*180/PI()))) -> 100.53386 | CZ8: =CY8/360*6400 -> 1787.2687 | DA8: =CT8+2 -> 725 | DB8: =CU8 -> 428 | DC8: =((Koordinaten!$D$5-DA8)^2+(Koordinaten!$D$6-DB8)^2)^(1/2)*10 -> 2481.1489 | DD8: =VLOOKUP(Koordinaten!$E$12,Tabelle1!$G$4:$AB$8,22,FALSE) -> 1142.6151 | DE8: =IF((Koordinaten!$D$7-Koordinaten!$E$7)>0,DD8+Koordinaten!$E$16,DD8-Koordinaten!$E$16) -> 1133.5014 | DF8: =IF((Koordinaten!$F$6-DB8)<0,IF((Koordinaten!$F$5-DA8)>0,360+(ATAN((Koordinaten!$F$5-DA8)/(Koordinaten!$F$6-DB8))*180/PI()),IF((Koordinaten!$F$5-DA8)<0,0+(ATAN((Koordinaten!$F$5-DA8)/(Koordinaten!$F$6-DB8))*180/PI()))),IF((Koordinaten!$F$5-DA8)<0,180+(ATAN((Koordinaten!$F$5-DA8)/(Koordinaten!$F$6-DB8))*180/PI()),180+(ATAN((Koordinaten!$F$5-DA8)/(Koordinaten!$F$6-DB8))*180/PI()))) -> 100.44943 | DG8: =DF8/360*6400 -> 1785.7676
I10: Polynome Delta ELEV Höhe | AN10: 4 | AO10: SE | AP10: =Koordinaten!$E$5 -> 707 | AQ10: =Koordinaten!$E$6 -> 428 | AR10: =((Koordinaten!$D$5-AP10)^2+(Koordinaten!$D$6-AQ10)^2)^(1/2)*10 -> 2304.3654 | AS10: =VLOOKUP(Koordinaten!$E$12,Tabelle1!$G$4:$AB$8,13,FALSE) -> 1134.6016 | AT10: =IF((Koordinaten!$D$7-Koordinaten!$E$7)>0,AS10+Koordinaten!$E$16,AS10-Koordinaten!$E$16) -> 1125.488 | AU10: =IF((Koordinaten!$F$6-AQ10)<0,IF((Koordinaten!$F$5-AP10)>0,360+(ATAN((Koordinaten!$F$5-AP10)/(Koordinaten!$F$6-AQ10))*180/PI()),IF((Koordinaten!$F$5-AP10)<0,0+(ATAN((Koordinaten!$F$5-AP10)/(Koordinaten!$F$6-AQ10))*180/PI()))),IF((Koordinaten!$F$5-AP10)<0,180+(ATAN((Koordinaten!$F$5-AP10)/(Koordinaten!$F$6-AQ10))*180/PI()),180+(ATAN((Koordinaten!$F$5-AP10)/(Koordinaten!$F$6-AQ10))*180/PI()))) -> 101.26117 | AV10: =AU10/360*6400 -> 1800.1986 | AW10: =AP10+1.414 -> 708.414 | AX10: =AQ10-1.414 -> 426.586 | AY10: =((Koordinaten!$D$5-AW10)^2+(Koordinaten!$D$6-AX10)^2)^(1/2)*10 -> 2321.021 | AZ10: =VLOOKUP(Koordinaten!$E$12,Tabelle1!$G$4:$AB$8,14,FALSE) -> 1135.6959 | BA10: =IF((Koordinaten!$D$7-Koordinaten!$E$7)>0,AZ10+Koordinaten!$E$16,AZ10-Koordinaten!$E$16) -> 1126.5822 | BB10: =IF((Koordinaten!$F$6-AX10)<0,IF((Koordinaten!$F$5-AW10)>0,360+(ATAN((Koordinaten!$F$5-AW10)/(Koordinaten!$F$6-AX10))*180/PI()),IF((Koordinaten!$F$5-AW10)<0,0+(ATAN((Koordinaten!$F$5-AW10)/(Koordinaten!$F$6-AX10))*180/PI()))),IF((Koordinaten!$F$5-AW10)<0,180+(ATAN((Koordinaten!$F$5-AW10)/(Koordinaten!$F$6-AX10))*180/PI()),180+(ATAN((Koordinaten!$F$5-AW10)/(Koordinaten!$F$6-AX10))*180/PI()))) -> 101.53534 | BC10: =BB10/360*6400 -> 1805.0727 | BD10: =AW10+1.414 -> 709.828 | BE10: =AX10-1.414 -> 425.172 | BF10: =((Koordinaten!$D$5-BD10)^2+(Koordinaten!$D$6-BE10)^2)^(1/2)*10 -> 2337.7291 | BG10: =VLOOKUP(Koordinaten!$E$12,Tabelle1!$G$4:$AB$8,15,FALSE) -> 1136.7386 | BH10: =IF((Koordinaten!$D$7-Koordinaten!$E$7)>0,BG10+Koordinaten!$E$16,BG10-Koordinaten!$E$16) -> 1127.6249 | BI10: =IF((Koordinaten!$F$6-BE10)<0,IF((Koordinaten!$F$5-BD10)>0,360+(ATAN((Koordinaten!$F$5-BD10)/(Koordinaten!$F$6-BE10))*180/PI()),IF((Koordinaten!$F$5-BD10)<0,0+(ATAN((Koordinaten!$F$5-BD10)/(Koordinaten!$F$6-BE10))*180/PI()))),IF((Koordinaten!$F$5-BD10)<0,180+(ATAN((Koordinaten!$F$5-BD10)/(Koordinaten!$F$6-BE10))*180/PI()),180+(ATAN((Koordinaten!$F$5-BD10)/(Koordinaten!$F$6-BE10))*180/PI()))) -> 101.8056 | BJ10: =BI10/360*6400 -> 1809.8773 | BK10: =BD10+1.414 -> 711.242 | BL10: =BE10-1.414 -> 423.758 | BM10: =((Koordinaten!$D$5-BK10)^2+(Koordinaten!$D$6-BL10)^2)^(1/2)*10 -> 2354.4883 | BN10: =VLOOKUP(Koordinaten!$E$12,Tabelle1!$G$4:$AB$8,16,FALSE) -> 1137.73 | BO10: =IF((Koordinaten!$D$7-Koordinaten!$E$7)>0,BN10+Koordinaten!$E$16,BN10-Koordinaten!$E$16) -> 1128.6163 | BP10: =IF((Koordinaten!$F$6-BL10)<0,IF((Koordinaten!$F$5-BK10)>0,360+(ATAN((Koordinaten!$F$5-BK10)/(Koordinaten!$F$6-BL10))*180/PI()),IF((Koordinaten!$F$5-BK10)<0,0+(ATAN((Koordinaten!$F$5-BK10)/(Koordinaten!$F$6-BL10))*180/PI()))),IF((Koordinaten!$F$5-BK10)<0,180+(ATAN((Koordinaten!$F$5-BK10)/(Koordinaten!$F$6-BL10))*180/PI()),180+(ATAN((Koordinaten!$F$5-BK10)/(Koordinaten!$F$6-BL10))*180/PI()))) -> 102.07202 | BQ10: =BP10/360*6400 -> 1814.6136 | BR10: =BK10+1.414 -> 712.656 | BS10: =BL10-1.414 -> 422.344 | BT10: =((Koordinaten!$D$5-BR10)^2+(Koordinaten!$D$6-BS10)^2)^(1/2)*10 -> 2371.2978 | BU10: =VLOOKUP(Koordinaten!$E$12,Tabelle1!$G$4:$AB$8,17,FALSE) -> 1138.6704 | BV10: =IF((Koordinaten!$D$7-Koordinaten!$E$7)>0,BU10+Koordinaten!$E$16,BU10-Koordinaten!$E$16) -> 1129.5567 | BW10: =IF((Koordinaten!$F$6-BS10)<0,IF((Koordinaten!$F$5-BR10)>0,360+(ATAN((Koordinaten!$F$5-BR10)/(Koordinaten!$F$6-BS10))*180/PI()),IF((Koordinaten!$F$5-BR10)<0,0+(ATAN((Koordinaten!$F$5-BR10)/(Koordinaten!$F$6-BS10))*180/PI()))),IF((Koordinaten!$F$5-BR10)<0,180+(ATAN((Koordinaten!$F$5-BR10)/(Koordinaten!$F$6-BS10))*180/PI()),180+(ATAN((Koordinaten!$F$5-BR10)/(Koordinaten!$F$6-BS10))*180/PI()))) -> 102.33466 | BX10: =BW10/360*6400 -> 1819.2829 | BY10: =BR10+1.414 -> 714.07 | BZ10: =BS10-1.414 -> 420.93 | CA10: =((Koordinaten!$D$5-BY10)^2+(Koordinaten!$D$6-BZ10)^2)^(1/2)*10 -> 2388.1564 | CB10: =VLOOKUP(Koordinaten!$E$12,Tabelle1!$G$4:$AB$8,18,FALSE) -> 1139.56 | CC10: =IF((Koordinaten!$D$7-Koordinaten!$E$7)>0,CB10+Koordinaten!$E$16,CB10-Koordinaten!$E$16) -> 1130.4463 | CD10: =IF((Koordinaten!$F$6-BZ10)<0,IF((Koordinaten!$F$5-BY10)>0,360+(ATAN((Koordinaten!$F$5-BY10)/(Koordinaten!$F$6-BZ10))*180/PI()),IF((Koordinaten!$F$5-BY10)<0,0+(ATAN((Koordinaten!$F$5-BY10)/(Koordinaten!$F$6-BZ10))*180/PI()))),IF((Koordinaten!$F$5-BY10)<0,180+(ATAN((Koordinaten!$F$5-BY10)/(Koordinaten!$F$6-BZ10))*180/PI()),180+(ATAN((Koordinaten!$F$5-BY10)/(Koordinaten!$F$6-BZ10))*180/PI()))) -> 102.5936 | CE10: =CD10/360*6400 -> 1823.8863 | CF10: =BY10+1.414 -> 715.484 | CG10: =BZ10-1.414 -> 419.516 | CH10: =((Koordinaten!$D$5-CF10)^2+(Koordinaten!$D$6-CG10)^2)^(1/2)*10 -> 2405.0631 | CI10: =VLOOKUP(Koordinaten!$E$12,Tabelle1!$G$4:$AB$8,19,FALSE) -> 1140.3991 | CJ10: =IF((Koordinaten!$D$7-Koordinaten!$E$7)>0,CI10+Koordinaten!$E$16,CI10-Koordinaten!$E$16) -> 1131.2854 | CK10: =IF((Koordinaten!$F$6-CG10)<0,IF((Koordinaten!$F$5-CF10)>0,360+(ATAN((Koordinaten!$F$5-CF10)/(Koordinaten!$F$6-CG10))*180/PI()),IF((Koordinaten!$F$5-CF10)<0,0+(ATAN((Koordinaten!$F$5-CF10)/(Koordinaten!$F$6-CG10))*180/PI()))),IF((Koordinaten!$F$5-CF10)<0,180+(ATAN((Koordinaten!$F$5-CF10)/(Koordinaten!$F$6-CG10))*180/PI()),180+(ATAN((Koordinaten!$F$5-CF10)/(Koordinaten!$F$6-CG10))*180/PI()))) -> 102.84891 | CL10: =CK10/360*6400 -> 1828.4251 | CM10: =CF10+1.414 -> 716.898 | CN10: =CG10-1.414 -> 418.102 | CO10: =((Koordinaten!$D$5-CM10)^2+(Koordinaten!$D$6-CN10)^2)^(1/2)*10 -> 2422.0169 | CP10: =VLOOKUP(Koordinaten!$E$12,Tabelle1!$G$4:$AB$8,20,FALSE) -> 1141.1878 | CQ10: =IF((Koordinaten!$D$7-Koordinaten!$E$7)>0,CP10+Koordinaten!$E$16,CP10-Koordinaten!$E$16) -> 1132.0742 | CR10: =IF((Koordinaten!$F$6-CN10)<0,IF((Koordinaten!$F$5-CM10)>0,360+(ATAN((Koordinaten!$F$5-CM10)/(Koordinaten!$F$6-CN10))*180/PI()),IF((Koordinaten!$F$5-CM10)<0,0+(ATAN((Koordinaten!$F$5-CM10)/(Koordinaten!$F$6-CN10))*180/PI()))),IF((Koordinaten!$F$5-CM10)<0,180+(ATAN((Koordinaten!$F$5-CM10)/(Koordinaten!$F$6-CN10))*180/PI()),180+(ATAN((Koordinaten!$F$5-CM10)/(Koordinaten!$F$6-CN10))*180/PI()))) -> 103.10065 | CS10: =CR10/360*6400 -> 1832.9004 | CT10: =CM10+1.414 -> 718.312 | CU10: =CN10-1.414 -> 416.688 | CV10: =((Koordinaten!$D$5-CT10)^2+(Koordinaten!$D$6-CU10)^2)^(1/2)*10 -> 2439.0167 | CW10: =VLOOKUP(Koordinaten!$E$12,Tabelle1!$G$4:$AB$8,21,FALSE) -> 1141.9264 | CX10: =IF((Koordinaten!$D$7-Koordinaten!$E$7)>0,CW10+Koordinaten!$E$16,CW10-Koordinaten!$E$16) -> 1132.8128 | CY10: =IF((Koordinaten!$F$6-CU10)<0,IF((Koordinaten!$F$5-CT10)>0,360+(ATAN((Koordinaten!$F$5-CT10)/(Koordinaten!$F$6-CU10))*180/PI()),IF((Koordinaten!$F$5-CT10)<0,0+(ATAN((Koordinaten!$F$5-CT10)/(Koordinaten!$F$6-CU10))*180/PI()))),IF((Koordinaten!$F$5-CT10)<0,180+(ATAN((Koordinaten!$F$5-CT10)/(Koordinaten!$F$6-CU10))*180/PI()),180+(ATAN((Koordinaten!$F$5-CT10)/(Koordinaten!$F$6-CU10))*180/PI()))) -> 103.34888 | CZ10: =CY10/360*6400 -> 1837.3135 | DA10: =CT10+1.414 -> 719.726 | DB10: =CU10-1.414 -> 415.274 | DC10: =((Koordinaten!$D$5-DA10)^2+(Koordinaten!$D$6-DB10)^2)^(1/2)*10 -> 2456.0618 | DD10: =VLOOKUP(Koordinaten!$E$12,Tabelle1!$G$4:$AB$8,22,FALSE) -> 1142.6151 | DE10: =IF((Koordinaten!$D$7-Koordinaten!$E$7)>0,DD10+Koordinaten!$E$16,DD10-Koordinaten!$E$16) -> 1133.5014 | DF10: =IF((Koordinaten!$F$6-DB10)<0,IF((Koordinaten!$F$5-DA10)>0,360+(ATAN((Koordinaten!$F$5-DA10)/(Koordinaten!$F$6-DB10))*180/PI()),IF((Koordinaten!$F$5-DA10)<0,0+(ATAN((Koordinaten!$F$5-DA10)/(Koordinaten!$F$6-DB10))*180/PI()))),IF((Koordinaten!$F$5-DA10)<0,180+(ATAN((Koordinaten!$F$5-DA10)/(Koordinaten!$F$6-DB10))*180/PI()),180+(ATAN((Koordinaten!$F$5-DA10)/(Koordinaten!$F$6-DB10))*180/PI()))) -> 103.59367 | DG10: =DF10/360*6400 -> 1841.6653
F11: mil - 0 Ringe | G11: 0 | H11: =IF(Koordinaten!$D$7-Koordinaten!$E$7<0,(Koordinaten!$D$7-Koordinaten!$E$7)*(-1),Koordinaten!$D$7-Koordinaten!$E$7) -> 50 | I11: =AH11*H11^5+AG11*H11^4+AF11*H11^3+AE11*H11^2+AD11*H11+AC11 -> 60.742047 | AC11: 60.0589 | AD11: =-0.0397207 -> -0.0397207 | AE11: 0.00152269 | AF11: =-0.0000102995 -> -1.02995e-05 | AG11: 2.39832e-08
F12: mil - 1 Ring | G12: 1 | H12: =IF(Koordinaten!$D$7-Koordinaten!$E$7<0,(Koordinaten!$D$7-Koordinaten!$E$7)*(-1),Koordinaten!$D$7-Koordinaten!$E$7) -> 50 | I12: =AH12*H12^5+AG12*H12^4+AF12*H12^3+AE12*H12^2+AD12*H12+AC12 -> 27.046923 | AC12: 27 | AD12: =-0.000694771 -> -0.000694771 | AE12: 3.33625e-05 | AF12: =-0.00000000956533 -> -9.56533e-09 | AG12: =-0.0000000000907787 -> -9.07787e-11 | AH12: 5.70939e-14 | AN12: 5 | AO12: S | AP12: =Koordinaten!$E$5 -> 707 | AQ12: =Koordinaten!$E$6 -> 428 | AR12: =((Koordinaten!$D$5-AP12)^2+(Koordinaten!$D$6-AQ12)^2)^(1/2)*10 -> 2304.3654 | AS12: =VLOOKUP(Koordinaten!$E$12,Tabelle1!$G$4:$AB$8,13,FALSE) -> 1134.6016 | AT12: =IF((Koordinaten!$D$7-Koordinaten!$E$7)>0,AS12+Koordinaten!$E$16,AS12-Koordinaten!$E$16) -> 1125.488 | AU12: =IF((Koordinaten!$F$6-AQ12)<0,IF((Koordinaten!$F$5-AP12)>0,360+(ATAN((Koordinaten!$F$5-AP12)/(Koordinaten!$F$6-AQ12))*180/PI()),IF((Koordinaten!$F$5-AP12)<0,0+(ATAN((Koordinaten!$F$5-AP12)/(Koordinaten!$F$6-AQ12))*180/PI()))),IF((Koordinaten!$F$5-AP12)<0,180+(ATAN((Koordinaten!$F$5-AP12)/(Koordinaten!$F$6-AQ12))*180/PI()),180+(ATAN((Koordinaten!$F$5-AP12)/(Koordinaten!$F$6-AQ12))*180/PI()))) -> 101.26117 | AV12: =AU12/360*6400 -> 1800.1986 | AW12: =AP12 -> 707 | AX12: =AQ12-2 -> 426 | AY12: =((Koordinaten!$D$5-AW12)^2+(Koordinaten!$D$6-AX12)^2)^(1/2)*10 -> 2308.3544 | AZ12: =VLOOKUP(Koordinaten!$E$12,Tabelle1!$G$4:$AB$8,14,FALSE) -> 1135.6959 | BA12: =IF((Koordinaten!$D$7-Koordinaten!$E$7)>0,AZ12+Koordinaten!$E$16,AZ12-Koordinaten!$E$16) -> 1126.5822 | BB12: =IF((Koordinaten!$F$6-AX12)<0,IF((Koordinaten!$F$5-AW12)>0,360+(ATAN((Koordinaten!$F$5-AW12)/(Koordinaten!$F$6-AX12))*180/PI()),IF((Koordinaten!$F$5-AW12)<0,0+(ATAN((Koordinaten!$F$5-AW12)/(Koordinaten!$F$6-AX12))*180/PI()))),IF((Koordinaten!$F$5-AW12)<0,180+(ATAN((Koordinaten!$F$5-AW12)/(Koordinaten!$F$6-AX12))*180/PI()),180+(ATAN((Koordinaten!$F$5-AW12)/(Koordinaten!$F$6-AX12))*180/PI()))) -> 101.74804 | BC12: =BB12/360*6400 -> 1808.854 | BD12: =AW12 -> 707 | BE12: =AX12-2 -> 424 | BF12: =((Koordinaten!$D$5-BD12)^2+(Koordinaten!$D$6-BE12)^2)^(1/2)*10 -> 2312.5095 | BG12: =VLOOKUP(Koordinaten!$E$12,Tabelle1!$G$4:$AB$8,15,FALSE) -> 1136.7386 | BH12: =IF((Koordinaten!$D$7-Koordinaten!$E$7)>0,BG12+Koordinaten!$E$16,BG12-Koordinaten!$E$16) -> 1127.6249 | BI12: =IF((Koordinaten!$F$6-BE12)<0,IF((Koordinaten!$F$5-BD12)>0,360+(ATAN((Koordinaten!$F$5-BD12)/(Koordinaten!$F$6-BE12))*180/PI()),IF((Koordinaten!$F$5-BD12)<0,0+(ATAN((Koordinaten!$F$5-BD12)/(Koordinaten!$F$6-BE12))*180/PI()))),IF((Koordinaten!$F$5-BD12)<0,180+(ATAN((Koordinaten!$F$5-BD12)/(Koordinaten!$F$6-BE12))*180/PI()),180+(ATAN((Koordinaten!$F$5-BD12)/(Koordinaten!$F$6-BE12))*180/PI()))) -> 102.23319 | BJ12: =BI12/360*6400 -> 1817.479 | BK12: =BD12 -> 707 | BL12: =BE12-2 -> 422 | BM12: =((Koordinaten!$D$5-BK12)^2+(Koordinaten!$D$6-BL12)^2)^(1/2)*10 -> 2316.8297 | BN12: =VLOOKUP(Koordinaten!$E$12,Tabelle1!$G$4:$AB$8,16,FALSE) -> 1137.73 | BO12: =IF((Koordinaten!$D$7-Koordinaten!$E$7)>0,BN12+Koordinaten!$E$16,BN12-Koordinaten!$E$16) -> 1128.6163 | BP12: =IF((Koordinaten!$F$6-BL12)<0,IF((Koordinaten!$F$5-BK12)>0,360+(ATAN((Koordinaten!$F$5-BK12)/(Koordinaten!$F$6-BL12))*180/PI()),IF((Koordinaten!$F$5-BK12)<0,0+(ATAN((Koordinaten!$F$5-BK12)/(Koordinaten!$F$6-BL12))*180/PI()))),IF((Koordinaten!$F$5-BK12)<0,180+(ATAN((Koordinaten!$F$5-BK12)/(Koordinaten!$F$6-BL12))*180/PI()),180+(ATAN((Koordinaten!$F$5-BK12)/(Koordinaten!$F$6-BL12))*180/PI()))) -> 102.71657 | BQ12: =BP12/360*6400 -> 1826.0724 | BR12: =BK12 -> 707 | BS12: =BL12-2 -> 420 | BT12: =((Koordinaten!$D$5-BR12)^2+(Koordinaten!$D$6-BS12)^2)^(1/2)*10 -> 2321.3143 | BU12: =VLOOKUP(Koordinaten!$E$12,Tabelle1!$G$4:$AB$8,17,FALSE) -> 1138.6704 | BV12: =IF((Koordinaten!$D$7-Koordinaten!$E$7)>0,BU12+Koordinaten!$E$16,BU12-Koordinaten!$E$16) -> 1129.5567 | BW12: =IF((Koordinaten!$F$6-BS12)<0,IF((Koordinaten!$F$5-BR12)>0,360+(ATAN((Koordinaten!$F$5-BR12)/(Koordinaten!$F$6-BS12))*180/PI()),IF((Koordinaten!$F$5-BR12)<0,0+(ATAN((Koordinaten!$F$5-BR12)/(Koordinaten!$F$6-BS12))*180/PI()))),IF((Koordinaten!$F$5-BR12)<0,180+(ATAN((Koordinaten!$F$5-BR12)/(Koordinaten!$F$6-BS12))*180/PI()),180+(ATAN((Koordinaten!$F$5-BR12)/(Koordinaten!$F$6-BS12))*180/PI()))) -> 103.19812 | BX12: =BW12/360*6400 -> 1834.6333 | BY12: =BR12 -> 707 | BZ12: =BS12-2 -> 418 | CA12: =((Koordinaten!$D$5-BY12)^2+(Koordinaten!$D$6-BZ12)^2)^(1/2)*10 -> 2325.9622 | CB12: =VLOOKUP(Koordinaten!$E$12,Tabelle1!$G$4:$AB$8,18,FALSE) -> 1139.56 | CC12: =IF((Koordinaten!$D$7-Koordinaten!$E$7)>0,CB12+Koordinaten!$E$16,CB12-Koordinaten!$E$16) -> 1130.4463 | CD12: =IF((Koordinaten!$F$6-BZ12)<0,IF((Koordinaten!$F$5-BY12)>0,360+(ATAN((Koordinaten!$F$5-BY12)/(Koordinaten!$F$6-BZ12))*180/PI()),IF((Koordinaten!$F$5-BY12)<0,0+(ATAN((Koordinaten!$F$5-BY12)/(Koordinaten!$F$6-BZ12))*180/PI()))),IF((Koordinaten!$F$5-BY12)<0,180+(ATAN((Koordinaten!$F$5-BY12)/(Koordinaten!$F$6-BZ12))*180/PI()),180+(ATAN((Koordinaten!$F$5-BY12)/(Koordinaten!$F$6-BZ12))*180/PI()))) -> 103.67778 | CE12: =CD12/360*6400 -> 1843.1605 | CF12: =BY12 -> 707 | CG12: =BZ12-2 -> 416 | CH12: =((Koordinaten!$D$5-CF12)^2+(Koordinaten!$D$6-CG12)^2)^(1/2)*10 -> 2330.7724 | CI12: =VLOOKUP(Koordinaten!$E$12,Tabelle1!$G$4:$AB$8,19,FALSE) -> 1140.3991 | CJ12: =IF((Koordinaten!$D$7-Koordinaten!$E$7)>0,CI12+Koordinaten!$E$16,CI12-Koordinaten!$E$16) -> 1131.2854 | CK12: =IF((Koordinaten!$F$6-CG12)<0,IF((Koordinaten!$F$5-CF12)>0,360+(ATAN((Koordinaten!$F$5-CF12)/(Koordinaten!$F$6-CG12))*180/PI()),IF((Koordinaten!$F$5-CF12)<0,0+(ATAN((Koordinaten!$F$5-CF12)/(Koordinaten!$F$6-CG12))*180/PI()))),IF((Koordinaten!$F$5-CF12)<0,180+(ATAN((Koordinaten!$F$5-CF12)/(Koordinaten!$F$6-CG12))*180/PI()),180+(ATAN((Koordinaten!$F$5-CF12)/(Koordinaten!$F$6-CG12))*180/PI()))) -> 104.15549 | CL12: =CK12/360*6400 -> 1851.6531 | CM12: =CF12 -> 707 | CN12: =CG12-2 -> 414 | CO12: =((Koordinaten!$D$5-CM12)^2+(Koordinaten!$D$6-CN12)^2)^(1/2)*10 -> 2335.744 | CP12: =VLOOKUP(Koordinaten!$E$12,Tabelle1!$G$4:$AB$8,20,FALSE) -> 1141.1878 | CQ12: =IF((Koordinaten!$D$7-Koordinaten!$E$7)>0,CP12+Koordinaten!$E$16,CP12-Koordinaten!$E$16) -> 1132.0742 | CR12: =IF((Koordinaten!$F$6-CN12)<0,IF((Koordinaten!$F$5-CM12)>0,360+(ATAN((Koordinaten!$F$5-CM12)/(Koordinaten!$F$6-CN12))*180/PI()),IF((Koordinaten!$F$5-CM12)<0,0+(ATAN((Koordinaten!$F$5-CM12)/(Koordinaten!$F$6-CN12))*180/PI()))),IF((Koordinaten!$F$5-CM12)<0,180+(ATAN((Koordinaten!$F$5-CM12)/(Koordinaten!$F$6-CN12))*180/PI()),180+(ATAN((Koordinaten!$F$5-CM12)/(Koordinaten!$F$6-CN12))*180/PI()))) -> 104.63119 | CS12: =CR12/360*6400 -> 1860.1101 | CT12: =CM12 -> 707 | CU12: =CN12-2 -> 412 | CV12: =((Koordinaten!$D$5-CT12)^2+(Koordinaten!$D$6-CU12)^2)^(1/2)*10 -> 2340.8759 | CW12: =VLOOKUP(Koordinaten!$E$12,Tabelle1!$G$4:$AB$8,21,FALSE) -> 1141.9264 | CX12: =IF((Koordinaten!$D$7-Koordinaten!$E$7)>0,CW12+Koordinaten!$E$16,CW12-Koordinaten!$E$16) -> 1132.8128 | CY12: =IF((Koordinaten!$F$6-CU12)<0,IF((Koordinaten!$F$5-CT12)>0,360+(ATAN((Koordinaten!$F$5-CT12)/(Koordinaten!$F$6-CU12))*180/PI()),IF((Koordinaten!$F$5-CT12)<0,0+(ATAN((Koordinaten!$F$5-CT12)/(Koordinaten!$F$6-CU12))*180/PI()))),IF((Koordinaten!$F$5-CT12)<0,180+(ATAN((Koordinaten!$F$5-CT12)/(Koordinaten!$F$6-CU12))*180/PI()),180+(ATAN((Koordinaten!$F$5-CT12)/(Koordinaten!$F$6-CU12))*180/PI()))) -> 105.10485 | CZ12: =CY12/360*6400 -> 1868.5307 | DA12: =CT12 -> 707 | DB12: =CU12-2 -> 410 | DC12: =((Koordinaten!$D$5-DA12)^2+(Koordinaten!$D$6-DB12)^2)^(1/2)*10 -> 2346.1671 | DD12: =VLOOKUP(Koordinaten!$E$12,Tabelle1!$G$4:$AB$8,22,FALSE) -> 1142.6151 | DE12: =IF((Koordinaten!$D$7-Koordinaten!$E$7)>0,DD12+Koordinaten!$E$16,DD12-Koordinaten!$E$16) -> 1133.5014 | DF12: =IF((Koordinaten!$F$6-DB12)<0,IF((Koordinaten!$F$5-DA12)>0,360+(ATAN((Koordinaten!$F$5-DA12)/(Koordinaten!$F$6-DB12))*180/PI()),IF((Koordinaten!$F$5-DA12)<0,0+(ATAN((Koordinaten!$F$5-DA12)/(Koordinaten!$F$6-DB12))*180/PI()))),IF((Koordinaten!$F$5-DA12)<0,180+(ATAN((Koordinaten!$F$5-DA12)/(Koordinaten!$F$6-DB12))*180/PI()),180+(ATAN((Koordinaten!$F$5-DA12)/(Koordinaten!$F$6-DB12))*180/PI()))) -> 105.5764 | DG12: =DF12/360*6400 -> 1876.9138
F13: mil - 2 Ringe | G13: 2 | H13: =IF(Koordinaten!$D$7-Koordinaten!$E$7<0,(Koordinaten!$D$7-Koordinaten!$E$7)*(-1),Koordinaten!$D$7-Koordinaten!$E$7) -> 50 | I13: =AH13*H13^5+AG13*H13^4+AF13*H13^3+AE13*H13^2+AD13*H13+AC13 -> 16.97044 | AC13: 17.7179 | AD13: =-0.0177179 -> -0.0177179 | AE13: 5.89459e-05 | AF13: =-0.0000000730769 -> -7.30769e-08 | AG13: 3.27635e-11
